[2023-08-25 13:54:48,148 - INFO - utils - Note: NumExpr detected 12 cores but "NUMEXPR_MAX_THREADS" not set, so enforcing safe limit of 8.]
[2023-08-25 13:54:48,149 - INFO - utils - NumExpr defaulting to 8 threads.]
[2023-08-25 13:54:51,942 - INFO - train -  >>>> stage Training <<<< started !]
[2023-08-25 13:54:52,257 - ERROR - train - Got invalid value               precision    recall  f1-score   support

           0       0.81      0.81      0.81        16
           1       0.96      1.00      0.98        43
           2       0.86      0.75      0.80        16

    accuracy                           0.91        75
   macro avg       0.88      0.85      0.86        75
weighted avg       0.90      0.91      0.90        75
 for metric 'Classification Report' (timestamp=1692951892253). Please specify value as a valid double (64-bit floating point)]
Traceback (most recent call last):
  File "d:\old work\sleep_disorder_prediction\src\train.py", line 68, in <module>
    obj3.training(preprocess_path)
  File "d:\old work\sleep_disorder_prediction\src\train.py", line 40, in training
    mlflow.log_metric("Classification Report", report)
  File "C:\Users\ak064\AppData\Local\Programs\Python\Python310\lib\site-packages\mlflow\tracking\fluent.py", line 647, in log_metric
    MlflowClient().log_metric(run_id, key, value, get_current_time_millis(), step or 0)
  File "C:\Users\ak064\AppData\Local\Programs\Python\Python310\lib\site-packages\mlflow\tracking\client.py", line 703, in log_metric
    self._tracking_client.log_metric(run_id, key, value, timestamp, step)
  File "C:\Users\ak064\AppData\Local\Programs\Python\Python310\lib\site-packages\mlflow\tracking\_tracking_service\client.py", line 286, in log_metric
    self.store.log_metric(run_id, metric)
  File "C:\Users\ak064\AppData\Local\Programs\Python\Python310\lib\site-packages\mlflow\store\tracking\file_store.py", line 911, in log_metric
    _validate_metric(metric.key, metric.value, metric.timestamp, metric.step)
  File "C:\Users\ak064\AppData\Local\Programs\Python\Python310\lib\site-packages\mlflow\utils\validation.py", line 136, in _validate_metric
    raise MlflowException(
mlflow.exceptions.MlflowException: Got invalid value               precision    recall  f1-score   support

           0       0.81      0.81      0.81        16
           1       0.96      1.00      0.98        43
           2       0.86      0.75      0.80        16

    accuracy                           0.91        75
   macro avg       0.88      0.85      0.86        75
weighted avg       0.90      0.91      0.90        75
 for metric 'Classification Report' (timestamp=1692951892253). Please specify value as a valid double (64-bit floating point)
